Traceback (most recent call last):
  File "/opt/hostedtoolcache/Python/3.11.6/x64/lib/python3.11/site-packages/jupyter_cache/executors/utils.py", line 58, in single_nb_execution
    executenb(
  File "/opt/hostedtoolcache/Python/3.11.6/x64/lib/python3.11/site-packages/nbclient/client.py", line 1305, in execute
    return NotebookClient(nb=nb, resources=resources, km=km, **kwargs).execute()
           ^^^^^^^^^^^^^^^^^^^^^^^^^^^^^^^^^^^^^^^^^^^^^^^^^^^^^^^^^^^^^^^^^^^^^
  File "/opt/hostedtoolcache/Python/3.11.6/x64/lib/python3.11/site-packages/jupyter_core/utils/__init__.py", line 173, in wrapped
    return loop.run_until_complete(inner)
           ^^^^^^^^^^^^^^^^^^^^^^^^^^^^^^
  File "/opt/hostedtoolcache/Python/3.11.6/x64/lib/python3.11/asyncio/base_events.py", line 653, in run_until_complete
    return future.result()
           ^^^^^^^^^^^^^^^
  File "/opt/hostedtoolcache/Python/3.11.6/x64/lib/python3.11/site-packages/nbclient/client.py", line 705, in async_execute
    await self.async_execute_cell(
  File "/opt/hostedtoolcache/Python/3.11.6/x64/lib/python3.11/site-packages/nbclient/client.py", line 1058, in async_execute_cell
    await self._check_raise_for_error(cell, cell_index, exec_reply)
  File "/opt/hostedtoolcache/Python/3.11.6/x64/lib/python3.11/site-packages/nbclient/client.py", line 914, in _check_raise_for_error
    raise CellExecutionError.from_cell_and_msg(cell, exec_reply_content)
nbclient.exceptions.CellExecutionError: An error occurred while executing the following cell:
------------------
excluder = ExclusionContainer()

excluder.add_raster(CORINE, codes=(21, 22, 23, 24, 25, 27, 28, 29, 30, 33,
                                   34, 35, 36, 37, 38, 39, 40, 41, 42, 43, 44))

country = shapes.geometry.to_crs(excluder.crs)

masked, transform = shape_availability(country, excluder)
eligible_area = masked.sum() * excluder.res**2
eligible_share = masked.sum() * excluder.res**2 / country.geometry.item().area
------------------


[0;31m---------------------------------------------------------------------------[0m
[0;31mCPLE_OpenFailedError[0m                      Traceback (most recent call last)
File [0;32mrasterio/_base.pyx:310[0m, in [0;36mrasterio._base.DatasetBase.__init__[0;34m()[0m

File [0;32mrasterio/_base.pyx:221[0m, in [0;36mrasterio._base.open_dataset[0;34m()[0m

File [0;32mrasterio/_err.pyx:221[0m, in [0;36mrasterio._err.exc_wrap_pointer[0;34m()[0m

[0;31mCPLE_OpenFailedError[0m: data/corine.tif: No such file or directory

During handling of the above exception, another exception occurred:

[0;31mRasterioIOError[0m                           Traceback (most recent call last)
Cell [0;32mIn[4], line 8[0m
[1;32m      3[0m excluder[38;5;241m.[39madd_raster(CORINE, codes[38;5;241m=[39m([38;5;241m21[39m, [38;5;241m22[39m, [38;5;241m23[39m, [38;5;241m24[39m, [38;5;241m25[39m, [38;5;241m27[39m, [38;5;241m28[39m, [38;5;241m29[39m, [38;5;241m30[39m, [38;5;241m33[39m,
[1;32m      4[0m                                    [38;5;241m34[39m, [38;5;241m35[39m, [38;5;241m36[39m, [38;5;241m37[39m, [38;5;241m38[39m, [38;5;241m39[39m, [38;5;241m40[39m, [38;5;241m41[39m, [38;5;241m42[39m, [38;5;241m43[39m, [38;5;241m44[39m))
[1;32m      6[0m country [38;5;241m=[39m shapes[38;5;241m.[39mgeometry[38;5;241m.[39mto_crs(excluder[38;5;241m.[39mcrs)
[0;32m----> 8[0m masked, transform [38;5;241m=[39m [43mshape_availability[49m[43m([49m[43mcountry[49m[43m,[49m[43m [49m[43mexcluder[49m[43m)[49m
[1;32m      9[0m eligible_area [38;5;241m=[39m masked[38;5;241m.[39msum() [38;5;241m*[39m excluder[38;5;241m.[39mres[38;5;241m*[39m[38;5;241m*[39m[38;5;241m2[39m
[1;32m     10[0m eligible_share [38;5;241m=[39m masked[38;5;241m.[39msum() [38;5;241m*[39m excluder[38;5;241m.[39mres[38;5;241m*[39m[38;5;241m*[39m[38;5;241m2[39m [38;5;241m/[39m country[38;5;241m.[39mgeometry[38;5;241m.[39mitem()[38;5;241m.[39marea

File [0;32m/opt/hostedtoolcache/Python/3.11.6/x64/lib/python3.11/site-packages/atlite/gis.py:298[0m, in [0;36mshape_availability[0;34m(geometry, excluder)[0m
[1;32m    277[0m [38;5;250m[39m[38;5;124;03m"""[39;00m
[1;32m    278[0m [38;5;124;03mCompute the eligible area in one or more geometries.[39;00m
[1;32m    279[0m 
[0;32m   (...)[0m
[1;32m    295[0m [38;5;124;03m    Affine transform of the mask.[39;00m
[1;32m    296[0m [38;5;124;03m"""[39;00m
[1;32m    297[0m [38;5;28;01mif[39;00m [38;5;129;01mnot[39;00m excluder[38;5;241m.[39mall_open:
[0;32m--> 298[0m     [43mexcluder[49m[38;5;241;43m.[39;49m[43mopen_files[49m[43m([49m[43m)[49m
[1;32m    299[0m [38;5;28;01massert[39;00m geometry[38;5;241m.[39mcrs [38;5;241m==[39m excluder[38;5;241m.[39mcrs
[1;32m    301[0m bounds [38;5;241m=[39m rio[38;5;241m.[39mfeatures[38;5;241m.[39mbounds(geometry)

File [0;32m/opt/hostedtoolcache/Python/3.11.6/x64/lib/python3.11/site-packages/atlite/gis.py:486[0m, in [0;36mExclusionContainer.open_files[0;34m(self)[0m
[1;32m    484[0m raster [38;5;241m=[39m d[[38;5;124m"[39m[38;5;124mraster[39m[38;5;124m"[39m]
[1;32m    485[0m [38;5;28;01mif[39;00m [38;5;28misinstance[39m(raster, ([38;5;28mstr[39m, Path)):
[0;32m--> 486[0m     raster [38;5;241m=[39m [43mrio[49m[38;5;241;43m.[39;49m[43mopen[49m[43m([49m[43mraster[49m[43m)[49m
[1;32m    487[0m [38;5;28;01melse[39;00m:
[1;32m    488[0m     [38;5;28;01massert[39;00m [38;5;28misinstance[39m(raster, rio[38;5;241m.[39mDatasetReader)

File [0;32m/opt/hostedtoolcache/Python/3.11.6/x64/lib/python3.11/site-packages/rasterio/env.py:451[0m, in [0;36mensure_env_with_credentials.<locals>.wrapper[0;34m(*args, **kwds)[0m
[1;32m    448[0m     session [38;5;241m=[39m DummySession()
[1;32m    450[0m [38;5;28;01mwith[39;00m env_ctor(session[38;5;241m=[39msession):
[0;32m--> 451[0m     [38;5;28;01mreturn[39;00m [43mf[49m[43m([49m[38;5;241;43m*[39;49m[43margs[49m[43m,[49m[43m [49m[38;5;241;43m*[39;49m[38;5;241;43m*[39;49m[43mkwds[49m[43m)[49m

File [0;32m/opt/hostedtoolcache/Python/3.11.6/x64/lib/python3.11/site-packages/rasterio/__init__.py:304[0m, in [0;36mopen[0;34m(fp, mode, driver, width, height, count, crs, transform, dtype, nodata, sharing, **kwargs)[0m
[1;32m    301[0m path [38;5;241m=[39m _parse_path(raw_dataset_path)
[1;32m    303[0m [38;5;28;01mif[39;00m mode [38;5;241m==[39m [38;5;124m"[39m[38;5;124mr[39m[38;5;124m"[39m:
[0;32m--> 304[0m     dataset [38;5;241m=[39m [43mDatasetReader[49m[43m([49m[43mpath[49m[43m,[49m[43m [49m[43mdriver[49m[38;5;241;43m=[39;49m[43mdriver[49m[43m,[49m[43m [49m[43msharing[49m[38;5;241;43m=[39;49m[43msharing[49m[43m,[49m[43m [49m[38;5;241;43m*[39;49m[38;5;241;43m*[39;49m[43mkwargs[49m[43m)[49m
[1;32m    305[0m [38;5;28;01melif[39;00m mode [38;5;241m==[39m [38;5;124m"[39m[38;5;124mr+[39m[38;5;124m"[39m:
[1;32m    306[0m     dataset [38;5;241m=[39m get_writer_for_path(path, driver[38;5;241m=[39mdriver)(
[1;32m    307[0m         path, mode, driver[38;5;241m=[39mdriver, sharing[38;5;241m=[39msharing, [38;5;241m*[39m[38;5;241m*[39mkwargs
[1;32m    308[0m     )

File [0;32mrasterio/_base.pyx:312[0m, in [0;36mrasterio._base.DatasetBase.__init__[0;34m()[0m

[0;31mRasterioIOError[0m: data/corine.tif: No such file or directory

