Traceback (most recent call last):
  File "/opt/hostedtoolcache/Python/3.11.10/x64/lib/python3.11/site-packages/jupyter_cache/executors/utils.py", line 58, in single_nb_execution
    executenb(
  File "/opt/hostedtoolcache/Python/3.11.10/x64/lib/python3.11/site-packages/nbclient/client.py", line 1314, in execute
    return NotebookClient(nb=nb, resources=resources, km=km, **kwargs).execute()
           ^^^^^^^^^^^^^^^^^^^^^^^^^^^^^^^^^^^^^^^^^^^^^^^^^^^^^^^^^^^^^^^^^^^^^
  File "/opt/hostedtoolcache/Python/3.11.10/x64/lib/python3.11/site-packages/jupyter_core/utils/__init__.py", line 165, in wrapped
    return loop.run_until_complete(inner)
           ^^^^^^^^^^^^^^^^^^^^^^^^^^^^^^
  File "/opt/hostedtoolcache/Python/3.11.10/x64/lib/python3.11/asyncio/base_events.py", line 654, in run_until_complete
    return future.result()
           ^^^^^^^^^^^^^^^
  File "/opt/hostedtoolcache/Python/3.11.10/x64/lib/python3.11/site-packages/nbclient/client.py", line 709, in async_execute
    await self.async_execute_cell(
  File "/opt/hostedtoolcache/Python/3.11.10/x64/lib/python3.11/site-packages/nbclient/client.py", line 1062, in async_execute_cell
    await self._check_raise_for_error(cell, cell_index, exec_reply)
  File "/opt/hostedtoolcache/Python/3.11.10/x64/lib/python3.11/site-packages/nbclient/client.py", line 918, in _check_raise_for_error
    raise CellExecutionError.from_cell_and_msg(cell, exec_reply_content)
nbclient.exceptions.CellExecutionError: An error occurred while executing the following cell:
------------------
IVcurve=pvlib.pvsystem.singlediode(photocurrent=I_L, 
                             saturation_current=I_o, 
                             resistance_series=R_s, 
                             resistance_shunt=R_sh,
                             nNsVth=nNsVth, 
                             ivcurve_pnts=100, 
                             method='lambertw')
------------------


[0;31m---------------------------------------------------------------------------[0m
[0;31mTypeError[0m                                 Traceback (most recent call last)
Cell [0;32mIn[5], line 1[0m
[0;32m----> 1[0m IVcurve[38;5;241m=[39m[43mpvlib[49m[38;5;241;43m.[39;49m[43mpvsystem[49m[38;5;241;43m.[39;49m[43msinglediode[49m[43m([49m[43mphotocurrent[49m[38;5;241;43m=[39;49m[43mI_L[49m[43m,[49m[43m [49m
[1;32m      2[0m [43m                             [49m[43msaturation_current[49m[38;5;241;43m=[39;49m[43mI_o[49m[43m,[49m[43m [49m
[1;32m      3[0m [43m                             [49m[43mresistance_series[49m[38;5;241;43m=[39;49m[43mR_s[49m[43m,[49m[43m [49m
[1;32m      4[0m [43m                             [49m[43mresistance_shunt[49m[38;5;241;43m=[39;49m[43mR_sh[49m[43m,[49m
[1;32m      5[0m [43m                             [49m[43mnNsVth[49m[38;5;241;43m=[39;49m[43mnNsVth[49m[43m,[49m[43m [49m
[1;32m      6[0m [43m                             [49m[43mivcurve_pnts[49m[38;5;241;43m=[39;49m[38;5;241;43m100[39;49m[43m,[49m[43m [49m
[1;32m      7[0m [43m                             [49m[43mmethod[49m[38;5;241;43m=[39;49m[38;5;124;43m'[39;49m[38;5;124;43mlambertw[39;49m[38;5;124;43m'[39;49m[43m)[49m

[0;31mTypeError[0m: singlediode() got an unexpected keyword argument 'ivcurve_pnts'

