Traceback (most recent call last):
  File "/opt/hostedtoolcache/Python/3.11.12/x64/lib/python3.11/site-packages/jupyter_cache/executors/utils.py", line 58, in single_nb_execution
    executenb(
  File "/opt/hostedtoolcache/Python/3.11.12/x64/lib/python3.11/site-packages/nbclient/client.py", line 1319, in execute
    return NotebookClient(nb=nb, resources=resources, km=km, **kwargs).execute()
           ^^^^^^^^^^^^^^^^^^^^^^^^^^^^^^^^^^^^^^^^^^^^^^^^^^^^^^^^^^^^^^^^^^^^^
  File "/opt/hostedtoolcache/Python/3.11.12/x64/lib/python3.11/site-packages/jupyter_core/utils/__init__.py", line 165, in wrapped
    return loop.run_until_complete(inner)
           ^^^^^^^^^^^^^^^^^^^^^^^^^^^^^^
  File "/opt/hostedtoolcache/Python/3.11.12/x64/lib/python3.11/asyncio/base_events.py", line 654, in run_until_complete
    return future.result()
           ^^^^^^^^^^^^^^^
  File "/opt/hostedtoolcache/Python/3.11.12/x64/lib/python3.11/site-packages/nbclient/client.py", line 709, in async_execute
    await self.async_execute_cell(
  File "/opt/hostedtoolcache/Python/3.11.12/x64/lib/python3.11/site-packages/nbclient/client.py", line 1062, in async_execute_cell
    await self._check_raise_for_error(cell, cell_index, exec_reply)
  File "/opt/hostedtoolcache/Python/3.11.12/x64/lib/python3.11/site-packages/nbclient/client.py", line 918, in _check_raise_for_error
    raise CellExecutionError.from_cell_and_msg(cell, exec_reply_content)
nbclient.exceptions.CellExecutionError: An error occurred while executing the following cell:
------------------
IVcurve=pvlib.pvsystem.singlediode(photocurrent=I_L_NMOT, 
                             saturation_current=I_o_NMOT, 
                             resistance_series=R_s_NMOT, 
                             resistance_shunt=R_sh_NMOT,
                             nNsVth=a_NMOT, 
                             ivcurve_pnts=100, 
                             method='lambertw')
------------------


[31m---------------------------------------------------------------------------[39m
[31mTypeError[39m                                 Traceback (most recent call last)
[36mCell[39m[36m [39m[32mIn[5][39m[32m, line 1[39m
[32m----> [39m[32m1[39m IVcurve=[43mpvlib[49m[43m.[49m[43mpvsystem[49m[43m.[49m[43msinglediode[49m[43m([49m[43mphotocurrent[49m[43m=[49m[43mI_L_NMOT[49m[43m,[49m[43m [49m
[32m      2[39m [43m                             [49m[43msaturation_current[49m[43m=[49m[43mI_o_NMOT[49m[43m,[49m[43m [49m
[32m      3[39m [43m                             [49m[43mresistance_series[49m[43m=[49m[43mR_s_NMOT[49m[43m,[49m[43m [49m
[32m      4[39m [43m                             [49m[43mresistance_shunt[49m[43m=[49m[43mR_sh_NMOT[49m[43m,[49m
[32m      5[39m [43m                             [49m[43mnNsVth[49m[43m=[49m[43ma_NMOT[49m[43m,[49m[43m [49m
[32m      6[39m [43m                             [49m[43mivcurve_pnts[49m[43m=[49m[32;43m100[39;49m[43m,[49m[43m [49m
[32m      7[39m [43m                             [49m[43mmethod[49m[43m=[49m[33;43m'[39;49m[33;43mlambertw[39;49m[33;43m'[39;49m[43m)[49m

[31mTypeError[39m: singlediode() got an unexpected keyword argument 'ivcurve_pnts'

